<!DOCTYPE html>
<html lang="en">
<head>
    <meta charset="UTF-8">
    <title>Title</title>
</head>
<body>

</body>
<script>
    Promise.reject('err!!!')
        .then((res) => {
            console.log('success', res)
        }, (err) => {
            console.log('error', err)
        }).catch(err => {
        console.log('catch', err)
    })
    //error:err!!!


    Promise.resolve()
        .then(function success (res) {
            throw new Error('error!!!')
        }, function fail1 (err) {
            console.log('fail1', err)
        }).catch(function fail2 (err) {
        console.log('fail2', err)
    })

    //then的第一个参数抛出错误，不会被同级的回调函数fail1捕获，而是被catch捕获
    //因为同级的fail1用于上一级promise的错误状态
</script>
</html>